Workbook

Sheet Primitives
A1: Primitives: vertex and triangle counts of the 16 mesh generators
A2: Legend: yellow = input from the code; white = formula.
A3: Source: src/primitives/*.cpp (Library.h lists the scene's generator calls); exported counts and parameters: ts --export-docs 'primitives' (P01..P16).
A5: Primitive | B5: Generator call | C5: param a | D5: param b | E5: V formula | F5: V | G5: T formula | H5: T | I5: indices I = 3T | J5: bytes indexed 24V+4I | K5: bytes non-indexed 72T | L5: V export | M5: T export | N5: dV | O5: dT | P5: instances (export) | Q5: scene triangles T export x inst
A6: 1 cube | B6: createCube() | C6: - | D6: - | E6: 6 x 4 | F6: =6*4 | G6: 6 x 2 | H6: =6*2 | I6: =3*H6 | J6: =24*F6+4*I6 | K6: =72*H6 | L6: 24 | M6: 12 | N6: =F6-L6 | O6: =H6-M6 | P6: 24 | Q6: =M6*P6
A7: 2 cuboid | B7: createCube(), S non-uniform | C7: - | D7: - | E7: 6 x 4 | F7: =6*4 | G7: 6 x 2 | H7: =6*2 | I7: =3*H7 | J7: =24*F7+4*I7 | K7: =72*H7 | L7: 24 | M7: 12 | N7: =F7-L7 | O7: =H7-M7 | P7: 2443 | Q7: =M7*P7
A8: 3 sphere | B8: createSphere(36, 18) | C8: 36 | D8: 18 | E8: (k-1)s + 2 | F8: =(D8-1)*C8+2 | G8: 2s(k-1) | H8: =2*C8*(D8-1) | I8: =3*H8 | J8: =24*F8+4*I8 | K8: =72*H8 | L8: 614 | M8: 1224 | N8: =F8-L8 | O8: =H8-M8 | P8: 808 | Q8: =M8*P8
A9: 4 hemisphere | B9: createHemisphere(36, 9) | C9: 36 | D9: 9 | E9: s(k+1) + 2 | F9: =C9*(D9+1)+2 | G9: 2sk | H9: =2*C9*D9 | I9: =3*H9 | J9: =24*F9+4*I9 | K9: =72*H9 | L9: 362 | M9: 648 | N9: =F9-L9 | O9: =H9-M9 | P9: 10 | Q9: =M9*P9
A10: 5 cylinder | B10: createCylinder(36) | C10: 36 | D10: - | E10: 4s + 2 | F10: =4*C10+2 | G10: 4s | H10: =4*C10 | I10: =3*H10 | J10: =24*F10+4*I10 | K10: =72*H10 | L10: 146 | M10: 144 | N10: =F10-L10 | O10: =H10-M10 | P10: 1358 | Q10: =M10*P10
A11: 6 frustum | B11: createCylinder(36, 0.03, 0.5, false) | C11: 36 | D11: - | E11: 2s | F11: =2*C11 | G11: 2s | H11: =2*C11 | I11: =3*H11 | J11: =24*F11+4*I11 | K11: =72*H11 | L11: 72 | M11: 72 | N11: =F11-L11 | O11: =H11-M11 | P11: 3 | Q11: =M11*P11
A12: 7 cone | B12: createCylinder(36, 0.5, 0, true) | C12: 36 | D12: - | E12: 3s + 1 | F12: =3*C12+1 | G12: 2s | H12: =2*C12 | I12: =3*H12 | J12: =24*F12+4*I12 | K12: =72*H12 | L12: 109 | M12: 72 | N12: =F12-L12 | O12: =H12-M12 | P12: 295 | Q12: =M12*P12
A13: 8 torus | B13: createTorus(0.35, 0.15, 36, 16) | C13: 36 | D13: 16 | E13: uv | F13: =C13*D13 | G13: 2uv | H13: =2*C13*D13 | I13: =3*H13 | J13: =24*F13+4*I13 | K13: =72*H13 | L13: 576 | M13: 1152 | N13: =F13-L13 | O13: =H13-M13 | P13: 97 | Q13: =M13*P13
A14: 9 wedge | B14: createWedge() | C14: - | D14: - | E14: 3 x 4 + 2 x 3 | F14: =3*4+2*3 | G14: 3 x 2 + 2 | H14: =3*2+2*1 | I14: =3*H14 | J14: =24*F14+4*I14 | K14: =72*H14 | L14: 18 | M14: 8 | N14: =F14-L14 | O14: =H14-M14 | P14: 6 | Q14: =M14*P14
A15: 10 tapered box | B15: createTaperedBox(0.8, 0.8) | C15: - | D15: - | E15: 6 x 4 | F15: =6*4 | G15: 6 x 2 | H15: =6*2 | I15: =3*H15 | J15: =24*F15+4*I15 | K15: =72*H15 | L15: 24 | M15: 12 | N15: =F15-L15 | O15: =H15-M15 | P15: 11 | Q15: =M15*P15
A16: 11 pyramid | B16: createPyramid() | C16: - | D16: - | E16: 4 + 4 x 3 | F16: =4+4*3 | G16: 2 + 4 | H16: =2+4 | I16: =3*H16 | J16: =24*F16+4*I16 | K16: =72*H16 | L16: 16 | M16: 6 | N16: =F16-L16 | O16: =H16-M16 | P16: 2 | Q16: =M16*P16
A17: 12 capsule | B17: createCapsule(16, 3, 0.25) | C17: 16 | D17: 3 | E17: 2cs + 2 | F17: =2*D17*C17+2 | G17: 4cs | H17: =4*D17*C17 | I17: =3*H17 | J17: =24*F17+4*I17 | K17: =72*H17 | L17: 98 | M17: 192 | N17: =F17-L17 | O17: =H17-M17 | P17: 364 | Q17: =M17*P17
A18: 13 annulus | B18: createAnnulus(0.43, 48) | C18: 48 | D18: - | E18: 4n | F18: =4*C18 | G18: 4n | H18: =4*C18 | I18: =3*H18 | J18: =24*F18+4*I18 | K18: =72*H18 | L18: 192 | M18: 192 | N18: =F18-L18 | O18: =H18-M18 | P18: 2 | Q18: =M18*P18
A19: 14 helix | B19: createHelix(0.475, 0.025, 5, 120, 6) | C19: 120 | D19: 6 | E19: (n+1)m + 2(m+1) | F19: =(C19+1)*D19+2*(D19+1) | G19: 2nm + 2m | H19: =2*C19*D19+2*D19 | I19: =3*H19 | J19: =24*F19+4*I19 | K19: =72*H19 | L19: 740 | M19: 1452 | N19: =F19-L19 | O19: =H19-M19 | P19: 52 | Q19: =M19*P19
A20: 15 grass blade | B20: createGrassBlade() | C20: - | D20: 3 | E20: 2 x rows + 1 | F20: =2*D20+1 | G20: 2(rows-1) + 1 | H20: =2*(D20-1)+1 | I20: =3*H20 | J20: =24*F20+4*I20 | K20: =72*H20 | L20: 7 | M20: 5 | N20: =F20-L20 | O20: =H20-M20 | P20: 0 | Q20: =M20*P20
A21: 16 terrain disc | B21: createTerrainDisc(130, 384, 36) | C21: 384 | D21: 130 | E21: 1 + ks | F21: =1+D21*C21 | G21: s(2k-1) - D | H21: =C21*(2*D21-1)-2016 | I21: =3*H21 | J21: =24*F21+4*I21 | K21: =72*H21 | L21: 49921 | M21: 97440 | N21: =F21-L21 | O21: =H21-M21 | P21: 1 | Q21: =M21*P21
A22: Scene total (parts) | P22: =SUM(P6:P21) | Q22: =SUM(Q6:Q21)
A23: dV = dT = 0: the closed-form counts match the exported meshes. Terrain: D = triangles dropped inside the entrance trench (export params.trench_dropped). Grass blade: 0 scene parts, 450000 GPU instances at EPIC.
A24: Bytes: 24-byte vertex (position + normal, 6 floats), 4-byte indices; non-indexed = 3 vertices per triangle (72 bytes). Exported bytes_indexed / bytes_non_indexed agree.
A26: Parametric equations (local space, unit size; export 'parametric' and 'axis')
A27: Primitive | B27: Point p(parameters) | J27: Placement / axis
A28: 1 cube | B28: corners: (0.5,-0.5,0.5) (0.5,-0.5,-0.5) (0.5,0.5,-0.5) (0.5,0.5,0.5) (-0.5,-0.5,-0.5) (-0.5,-0.5,0.5) (-0.5,0.5,0.5) (-0.5,0.5,-0.5) | J28: centred, x, y, z in [-0.5, 0.5]
A29: 2 cuboid | B29: corners: (0.5,-0.5,0.5) (0.5,-0.5,-0.5) (0.5,0.5,-0.5) (0.5,0.5,0.5) (-0.5,-0.5,-0.5) (-0.5,-0.5,0.5) (-0.5,0.5,0.5) (-0.5,0.5,-0.5) | J29: the cube mesh, S per part
A30: 3 sphere | B30: p = 0.5 (sin(theta) cos(phi), cos(theta), sin(theta) sin(phi)), theta = pi i / k, phi = 2 pi j / s; north half generated, south half by reflection y -> -y | J30: poles on Y
A31: 4 hemisphere | B31: p = (0.5 sin(theta) cos(phi), -0.5 + cos(theta), -0.5 sin(theta) sin(phi)), theta = (pi / 2) i / k, phi = 2 pi j / s; base disc y = -0.5 | J31: pole +Y, base disc at y = -0.5
A32: 5 cylinder | B32: p = (r cos(phi), r sin(phi), +-0.5), phi = 2 pi j / s; caps: centre + own ring (normal +-Z) | J32: axis Z
A33: 6 frustum | B33: p = (r(z) cos(phi), r(z) sin(phi), z), r(-0.5) = r_bottom, r(+0.5) = r_top; side normal (cos, sin, r_bottom - r_top) | J33: axis Z, open ends
A34: 7 cone | B34: cylinder generator with r_top = 0: apex (0, 0, 0.5), base disc z = -0.5 | J34: axis Z, apex +Z
A35: 8 torus | B35: p = ((R + r cos v) cos u, (R + r cos v) sin u, r sin v), n = (cos v cos u, cos v sin u, sin v) | J35: axis Z, R + r = 0.5, z in [-r, r]
A36: 9 wedge | B36: corners: (-0.5,-0.5,-0.5) (0.5,-0.5,-0.5) (0.5,-0.5,0.5) (-0.5,-0.5,0.5) (-0.5,0.5,-0.5) (0.5,0.5,-0.5) | J36: triangle (y, z) = (-,-) (-,+) (+,-) extruded along X; slope faces +Y +Z
A37: 10 tapered box | B37: corners: (-0.5,-0.5,-0.5) (0.5,-0.5,-0.5) (0.5,-0.5,0.5) (-0.5,-0.5,0.5) (-0.4,0.5,-0.4) (-0.4,0.5,0.4) (0.4,0.5,0.4) (0.4,0.5,-0.4) | J37: bottom 1 x 1 at y = -0.5, top at y = +0.5
A38: 11 pyramid | B38: corners: (-0.5,-0.5,-0.5) (0.5,-0.5,-0.5) (0.5,-0.5,0.5) (-0.5,-0.5,0.5) (0,0.5,0) | J38: base 1 x 1 at y = -0.5, apex +Y
... A43: 16 terrain disc | B43: polar grid r = R i / k, phi = 2 pi j / s, y = terrainHeight(x, z), n = terrain normal | J43: world units (radius R), Y up

Sheet Decomposition
A1: Decomposition: objects as hierarchies of primitive parts
A2: Legend: yellow = input from the code; white = formula.
A3: Source: ts --export-docs 'components' (S, R_deg, T, parent, colour, specular, shininess) and 'objects'; objects/*.cpp Builder. Rows below list every drawn part (leaf) of UAV-1 and of Soldier 1.
A5: 1. Object-level primitive totals (whole scene, from the export) | W5: 2. Parts per primitive (COUNTIFS over the part rows)
A6: Object | B6: Cube | C6: Wedge | D6: Tapered box | E6: Pyramid | F6: Sphere | G6: Hemisphere | H6: Capsule | I6: Cylinder | J6: Cylinder (frustum) | K6: Cone | L6: Torus | M6: Annulus | N6: Helix | O6: Terrain disc | P6: parts (sum) | Q6: parts export | R6: check | S6: groups | T6: animated nodes | W6: Primitive | X6: UAV-1 COUNTIFS | Y6: UAV-1 export | Z6: check | AA6: Soldier 1 COUNTIFS | AB6: Soldier 1 export | AC6: check
A7: Terrain | O7: 1 | P7: =SUM(B7:O7) | Q7: 1 | R7: =IF(P7=Q7,"OK","DIFF") | S7: 1 | T7: 0 | W7: Cube | X7: =COUNTIFS($C$45:$C$123,W7) | Y7: 34 | Z7: =IF(X7=Y7,"OK","DIFF") | AA7: =COUNTIFS($C$128:$C$202,W7) | AB7: 16 | AC7: =IF(AA7=AB7,"OK","DIFF")
A8: Backdrop | F8: 24 | I8: 10 | K8: 86 | P8: =SUM(B8:O8) | Q8: 120 | R8: =IF(P8=Q8,"OK","DIFF") | S8: 47 | T8: 3 | W8: Wedge | X8: =COUNTIFS($C$45:$C$123,W8) | Y8: 0 | Z8: =IF(X8=Y8,"OK","DIFF") | AA8: =COUNTIFS($C$128:$C$202,W8) | AB8: 0 | AC8: =IF(AA8=AB8,"OK","DIFF")
A9: Environment | B9: 46 | F9: 201 | H9: 57 | I9: 180 | K9: 168 | P9: =SUM(B9:O9) | Q9: 652 | R9: =IF(P9=Q9,"OK","DIFF") | S9: 89 | T9: 2 | W9: Tapered box | X9: =COUNTIFS($C$45:$C$123,W9) | Y9: 0 | Z9: =IF(X9=Y9,"OK","DIFF") | AA9: =COUNTIFS($C$128:$C$202,W9) | AB9: 1 | AC9: =IF(AA9=AB9,"OK","DIFF")
A10: Command Bunker | B10: 308 | C10: 1 | F10: 18 | G10: 1 | H10: 9 | I10: 90 | P10: =SUM(B10:O10) | Q10: 427 | R10: =IF(P10=Q10,"OK","DIFF") | S10: 18 | T10: 18 | W10: Pyramid | X10: =COUNTIFS($C$45:$C$123,W10) | Y10: 0 | Z10: =IF(X10=Y10,"OK","DIFF") | AA10: =COUNTIFS($C$128:$C$202,W10) | AB10: 0 | AC10: =IF(AA10=AB10,"OK","DIFF")
A11: Autonomous UAV | B11: 68 | F11: 26 | I11: 46 | J11: 2 | K11: 8 | L11: 8 | P11: =SUM(B11:O11) | Q11: 158 | R11: =IF(P11=Q11,"OK","DIFF") | S11: 34 | T11: 26 | W11: Sphere | X11: =COUNTIFS($C$45:$C$123,W11) | Y11: 13 | Z11: =IF(X11=Y11,"OK","DIFF") | AA11: =COUNTIFS($C$128:$C$202,W11) | AB11: 37 | AC11: =IF(AA11=AB11,"OK","DIFF")
A12: Base | B12: 556 | E12: 2 | F12: 41 | H12: 71 | I12: 271 | N12: 52 | P12: =SUM(B12:O12) | Q12: 993 | R12: =IF(P12=Q12,"OK","DIFF") | S12: 33 | T12: 0 | W12: Hemisphere | X12: =COUNTIFS($C$45:$C$123,W12) | Y12: 0 | Z12: =IF(X12=Y12,"OK","DIFF") | AA12: =COUNTIFS($C$128:$C$202,W12) | AB12: 1 | AC12: =IF(AA12=AB12,"OK","DIFF")
A13: Barracks hall | B13: 225 | F13: 2 | I13: 50 | P13: =SUM(B13:O13) | Q13: 277 | R13: =IF(P13=Q13,"OK","DIFF") | S13: 5 | T13: 1 | W13: Capsule | X13: =COUNTIFS($C$45:$C$123,W13) | Y13: 0 | Z13: =IF(X13=Y13,"OK","DIFF") | AA13: =COUNTIFS($C$128:$C$202,W13) | AB13: 0 | AC13: =IF(AA13=AB13,"OK","DIFF")
A14: UAV pads | B14: 4 | F14: 8 | I14: 4 | M14: 2 | P14: =SUM(B14:O14) | Q14: 18 | R14: =IF(P14=Q14,"OK","DIFF") | S14: 3 | T14: 0 | W14: Cylinder | X14: =COUNTIFS($C$45:$C$123,W14) | Y14: 23 | Z14: =IF(X14=Y14,"OK","DIFF") | AA14: =COUNTIFS($C$128:$C$202,W14) | AB14: 20 | AC14: =IF(AA14=AB14,"OK","DIFF")
A15: Target Rover | B15: 36 | F15: 72 | I15: 48 | P15: =SUM(B15:O15) | Q15: 156 | R15: =IF(P15=Q15,"OK","DIFF") | S15: 12 | T15: 48 | W15: Cylinder (frustum) | X15: =COUNTIFS($C$45:$C$123,W15) | Y15: 1 | Z15: =IF(X15=Y15,"OK","DIFF") | AA15: =COUNTIFS($C$128:$C$202,W15) | AB15: 0 | AC15: =IF(AA15=AB15,"OK","DIFF")
A16: Main Battle Tank | B16: 168 | C16: 1 | D16: 1 | F16: 5 | I16: 61 | L16: 19 | P16: =SUM(B16:O16) | Q16: 255 | R16: =IF(P16=Q16,"OK","DIFF") | S16: 29 | T16: 118 | W16: Cone | X16: =COUNTIFS($C$45:$C$123,W16) | Y16: 4 | Z16: =IF(X16=Y16,"OK","DIFF") | AA16: =COUNTIFS($C$128:$C$202,W16) | AB16: 0 | AC16: =IF(AA16=AB16,"OK","DIFF")
A17: Scout Helicopter | B17: 40 | F17: 21 | I17: 28 | J17: 1 | K17: 1 | P17: =SUM(B17:O17) | Q17: 91 | R17: =IF(P17=Q17,"OK","DIFF") | S17: 19 | T17: 17 | W17: Torus | X17: =COUNTIFS($C$45:$C$123,W17) | Y17: 4 | Z17: =IF(X17=Y17,"OK","DIFF") | AA17: =COUNTIFS($C$128:$C$202,W17) | AB17: 0 | AC17: =IF(AA17=AB17,"OK","DIFF")
A18: AA Gatling Gun | B18: 19 | F18: 4 | G18: 1 | I18: 54 | P18: =SUM(B18:O18) | Q18: 78 | R18: =IF(P18=Q18,"OK","DIFF") | S18: 5 | T18: 26 | W18: Annulus | X18: =COUNTIFS($C$45:$C$123,W18) | Y18: 0 | Z18: =IF(X18=Y18,"OK","DIFF") | AA18: =COUNTIFS($C$128:$C$202,W18) | AB18: 0 | AC18: =IF(AA18=AB18,"OK","DIFF")
A19: Air-defence radar | B19: 62 | F19: 3 | I19: 42 | K19: 1 | P19: =SUM(B19:O19) | Q19: 108 | R19: =IF(P19=Q19,"OK","DIFF") | S19: 4 | T19: 4 | W19: Helix | X19: =COUNTIFS($C$45:$C$123,W19) | Y19: 0 | Z19: =IF(X19=Y19,"OK","DIFF") | AA19: =COUNTIFS($C$128:$C$202,W19) | AB19: 0 | AC19: =IF(AA19=AB19,"OK","DIFF")
A20: SAM launcher | B20: 74 | F20: 5 | I20: 24 | K20: 1 | L20: 8 | P20: =SUM(B20:O20) | Q20: 112 | R20: =IF(P20=Q20,"OK","DIFF") | S20: 9 | T20: 10 | W20: Total parts | X20: =SUM(X7:X19) | Y20: =SUM(Y7:Y19) | Z20: =IF(X20=Y20,"OK","DIFF") | AA20: =SUM(AA7:AA19) | AB20: =SUM(AB7:AB19) | AC20: =IF(AA20=AB20,"OK","DIFF")
A21: MLRS rocket truck | B21: 45 | F21: 9 | I21: 52 | K21: 6 | L21: 24 | P21: =SUM(B21:O21) | Q21: 136 | R21: =IF(P21=Q21,"OK","DIFF") | S21: 22 | T21: 28
A22: Main Battle Tank 2 | B22: 168 | C22: 1 | D22: 1 | F22: 5 | I22: 61 | L22: 19 | P22: =SUM(B22:O22) | Q22: 255 | R22: =IF(P22=Q22,"OK","DIFF") | S22: 29 | T22: 118 | W22: UAV-1 export = controllable 'UAV-1 DRONE' (root UAV-00);
A23: Main Battle Tank 3 | B23: 168 | C23: 1 | D23: 1 | F23: 5 | I23: 61 | L23: 19 | P23: =SUM(B23:O23) | Q23: 255 | R23: =IF(P23=Q23,"OK","DIFF") | S23: 29 | T23: 118 | W23: the object 'Autonomous UAV' below counts both UAVs.
A24: Ammunition bunker | B24: 17 | C24: 2 | F24: 10 | H24: 8 | I24: 6 | P24: =SUM(B24:O24) | Q24: 43 | R24: =IF(P24=Q24,"OK","DIFF") | S24: 2 | T24: 0
A25: Camp camouflage | B25: 277 | F25: 48 | H25: 219 | I25: 90 | K25: 24 | P25: =SUM(B25:O25) | Q25: 658 | R25: =IF(P25=Q25,"OK","DIFF") | S25: 21 | T25: 0
A26: Boom barrier | B26: 17 | F26: 2 | I26: 1 | P26: =SUM(B26:O26) | Q26: 20 | R26: =IF(P26=Q26,"OK","DIFF") | S26: 2 | T26: 2
A27: Windsock | B27: 1 | I27: 14 | P27: =SUM(B27:O27) | Q27: 15 | R27: =IF(P27=Q27,"OK","DIFF") | S27: 7 | T27: 6
A28: Flag | B28: 40 | F28: 2 | I28: 5 | P28: =SUM(B28:O28) | Q28: 47 | R28: =IF(P28=Q28,"OK","DIFF") | S28: 14 | T28: 13
A29: Soldier 1 | B29: 16 | D29: 1 | F29: 37 | G29: 1 | I29: 20 | P29: =SUM(B29:O29) | Q29: 75 | R29: =IF(P29=Q29,"OK","DIFF") | S29: 20 | T29: 15
A30: Soldier 2 | B30: 16 | D30: 1 | F30: 37 | G30: 1 | I30: 20 | P30: =SUM(B30:O30) | Q30: 75 | R30: =IF(P30=Q30,"OK","DIFF") | S30: 20 | T30: 15
A31: Soldier 3 | B31: 16 | D31: 1 | F31: 37 | G31: 1 | I31: 20 | P31: =SUM(B31:O31) | Q31: 75 | R31: =IF(P31=Q31,"OK","DIFF") | S31: 20 | T31: 15
A32: Soldier 4 | B32: 16 | D32: 1 | F32: 37 | G32: 1 | I32: 20 | P32: =SUM(B32:O32) | Q32: 75 | R32: =IF(P32=Q32,"OK","DIFF") | S32: 20 | T32: 15
A33: Soldier 5 | B33: 16 | D33: 1 | F33: 37 | G33: 1 | I33: 20 | P33: =SUM(B33:O33) | Q33: 75 | R33: =IF(P33=Q33,"OK","DIFF") | S33: 20 | T33: 15
A34: Soldier 6 | B34: 16 | D34: 1 | F34: 37 | G34: 1 | I34: 20 | P34: =SUM(B34:O34) | Q34: 75 | R34: =IF(P34=Q34,"OK","DIFF") | S34: 20 | T34: 15
A35: Soldier 7 | B35: 16 | D35: 1 | F35: 37 | G35: 1 | I35: 20 | P35: =SUM(B35:O35) | Q35: 75 | R35: =IF(P35=Q35,"OK","DIFF") | S35: 20 | T35: 15
A36: Soldier 8 | B36: 16 | D36: 1 | F36: 37 | G36: 1 | I36: 20 | P36: =SUM(B36:O36) | Q36: 75 | R36: =IF(P36=Q36,"OK","DIFF") | S36: 20 | T36: 15
A37: Sky Clock | F37: 1 | P37: =SUM(B37:O37) | Q37: 1 | R37: =IF(P37=Q37,"OK","DIFF") | S37: 1 | T37: 0
A38: Scene total | B38: =SUM(B7:B37) | C38: =SUM(C7:C37) | D38: =SUM(D7:D37) | E38: =SUM(E7:E37) | F38: =SUM(F7:F37) | G38: =SUM(G7:G37) | H38: =SUM(H7:H37) | I38: =SUM(I7:I37) | ... Q38: =SUM(Q7:Q37) | S38: =SUM(S7:S37) | T38: =SUM(T7:T37)
A39: Instances (export) | B39: 2467 | C39: 6 | D39: 11 | E39: 2 | F39: 808 | G39: 10 | H39: 364 | I39: 1358 | J39: 3 | K39: 295 | L39: 97 | M39: 2 | N39: 52 | O39: 1 | P39: =SUM(B39:O39) | Q39: 5476
A40: check | B40: =IF(B38=B39,"OK","DIFF") | C40: =IF(C38=C39,"OK","DIFF") | D40: =IF(D38=D39,"OK","DIFF") | E40: =IF(E38=E39,"OK","DIFF") | F40: =IF(F38=F39,"OK","DIFF") | G40: =IF(G38=G39,"OK","DIFF") | H40: =IF(H38=H39,"OK","DIFF") | I40: =IF(I38=I39,"OK","DIFF") | ... Q40: =IF(Q38=Q39,"OK","DIFF")
A43: 3. UAV-1 (root UAV-00 'Autonomous UAV'): 79 drawn parts. M = T Ry Rx Rz S, world = parent_world M (the export's object 'Autonomous UAV' holds 2 UAVs).
...

Sheet Designs
A1: Designs: every object design, its instances and its primitives
A2: Legend: yellow = input from the code; white = formula.
A3: Source: ts --export-docs 'designs' (src/report/Designs.cpp) and src/report/PrimitiveColors.h. Section 19 of the report draws one card per design.
A5: 1. Designs: parts by primitive over all instances (yellow: export), totals and checks (formulas)
A6: Design | B6: Family | C6: x n | D6: parts / inst. | E6: parts total | F6: n x parts | G6: Cube | H6: Cuboid | I6: Wedge | J6: Tapered box | K6: Pyramid | L6: Sphere | M6: Hemisphere | N6: Capsule | O6: Cylinder | P6: Cylinder (frustum) | Q6: Cone | R6: Torus | S6: Annulus | T6: Helix | U6: Terrain disc | V6: sum | W6: check
A7: Soldier | B7: people | C7: 8 | D7: 75 | E7: 600 | F7: =IF(ISNUMBER(D7),C7*D7,E7) | H7: 128 | J7: 8 | L7: 296 | M7: 8 | O7: 160 | V7: =SUM(G7:U7) | W7: =IF(AND(V7=E7,F7=E7),"OK","DIFF")
A8: Main battle tank | B8: vehicles and aircraft | C8: 3 | D8: 255 | E8: 765 | F8: =IF(ISNUMBER(D8),C8*D8,E8) | H8: 504 | I8: 3 | J8: 3 | L8: 15 | O8: 183 | R8: 57 | V8: =SUM(G8:U8) | W8: =IF(AND(V8=E8,F8=E8),"OK","DIFF")
A9: MLRS rocket truck | B9: vehicles and aircraft | C9: 1 | D9: 106 | E9: 106 | F9: =IF(ISNUMBER(D9),C9*D9,E9) | G9: 1 | H9: 32 | L9: 3 | O9: 46 | R9: 24 | V9: =SUM(G9:U9) | W9: =IF(AND(V9=E9,F9=E9),"OK","DIFF")
A10: Scout helicopter | B10: vehicles and aircraft | C10: 1 | D10: 91 | E10: 91 | F10: =IF(ISNUMBER(D10),C10*D10,E10) | H10: 40 | L10: 21 | O10: 28 | P10: 1 | Q10: 1 | V10: =SUM(G10:U10) | W10: =IF(AND(V10=E10,F10=E10),"OK","DIFF")
A11: Autonomous UAV | B11: vehicles and aircraft | C11: 2 | D11: 55 | E11: 110 | F11: =IF(ISNUMBER(D11),C11*D11,E11) | H11: 36 | L11: 26 | O11: 38 | P11: 2 | R11: 8 | V11: =SUM(G11:U11) | W11: =IF(AND(V11=E11,F11=E11),"OK","DIFF")
A12: Cargo truck | B12: vehicles and aircraft | C12: 2 | D12: 31 | E12: 62 | F12: =IF(ISNUMBER(D12),C12*D12,E12) | H12: 30 | L12: 4 | O12: 28 | V12: =SUM(G12:U12) | W12: =IF(AND(V12=E12,F12=E12),"OK","DIFF")
A13: Target rover | B13: vehicles and aircraft | C13: 6 | D13: 26 | E13: 156 | F13: =IF(ISNUMBER(D13),C13*D13,E13) | H13: 36 | L13: 72 | O13: 48 | V13: =SUM(G13:U13) | W13: =IF(AND(V13=E13,F13=E13),"OK","DIFF")
A14: SAM launcher | B14: weapons and munitions | C14: 1 | D14: 107 | E14: 107 | F14: =IF(ISNUMBER(D14),C14*D14,E14) | G14: 1 | H14: 71 | L14: 4 | O14: 23 | R14: 8 | V14: =SUM(G14:U14) | W14: =IF(AND(V14=E14,F14=E14),"OK","DIFF")
A15: AA Gatling gun | B15: weapons and munitions | C15: 1 | D15: 58 | E15: 58 | F15: =IF(ISNUMBER(D15),C15*D15,E15) | H15: 19 | L15: 4 | M15: 1 | O15: 34 | V15: =SUM(G15:U15) | W15: =IF(AND(V15=E15,F15=E15),"OK","DIFF")
A16: SAM missile | B16: weapons and munitions | C16: 1 | D16: 5 | E16: 5 | F16: =IF(ISNUMBER(D16),C16*D16,E16) | H16: 2 | L16: 1 | O16: 1 | Q16: 1 | V16: =SUM(G16:U16) | W16: =IF(AND(V16=E16,F16=E16),"OK","DIFF")
A17: MLRS rocket | B17: weapons and munitions | C17: 6 | D17: 5 | E17: 30 | F17: =IF(ISNUMBER(D17),C17*D17,E17) | H17: 12 | L17: 6 | O17: 6 | Q17: 6 | V17: =SUM(G17:U17) | W17: =IF(AND(V17=E17,F17=E17),"OK","DIFF")
A18: UAV round | B18: weapons and munitions | C18: 8 | D18: 6 | E18: 48 | F18: =IF(ISNUMBER(D18),C18*D18,E18) | H18: 32 | O18: 8 | Q18: 8 | V18: =SUM(G18:U18) | W18: =IF(AND(V18=E18,F18=E18),"OK","DIFF")
A19: AA shell casing | B19: weapons and munitions | C19: 20 | D19: 1 | E19: 20 | F19: =IF(ISNUMBER(D19),C19*D19,E19) | O19: 20 | V19: =SUM(G19:U19) | W19: =IF(AND(V19=E19,F19=E19),"OK","DIFF")
A20: Command bunker | B20: buildings | C20: 1 | D20: 390 | E20: 390 | F20: =IF(ISNUMBER(D20),C20*D20,E20) | H20: 281 | I20: 1 | L20: 18 | M20: 1 | N20: 9 | O20: 80 | V20: =SUM(G20:U20) | W20: =IF(AND(V20=E20,F20=E20),"OK","DIFF")
A21: Barracks hall | B21: buildings | C21: 1 | D21: 277 | E21: 277 | F21: =IF(ISNUMBER(D21),C21*D21,E21) | H21: 225 | L21: 2 | O21: 50 | V21: =SUM(G21:U21) | W21: =IF(AND(V21=E21,F21=E21),"OK","DIFF")
A22: Air-defence radar | B22: buildings | C22: 1 | D22: 108 | E22: 108 | F22: =IF(ISNUMBER(D22),C22*D22,E22) | H22: 62 | L22: 3 | O22: 42 | Q22: 1 | V22: =SUM(G22:U22) | W22: =IF(AND(V22=E22,F22=E22),"OK","DIFF")
A23: Motor pool | B23: buildings | C23: 1 | D23: 4 | E23: 4 | F23: =IF(ISNUMBER(D23),C23*D23,E23) | H23: 1 | L23: 1 | O23: 2 | V23: =SUM(G23:U23) | W23: =IF(AND(V23=E23,F23=E23),"OK","DIFF")
A24: Helipad | B24: buildings | C24: 1 | D24: 51 | E24: 51 | F24: =IF(ISNUMBER(D24),C24*D24,E24) | H24: 31 | L24: 17 | O24: 3 | V24: =SUM(G24:U24) | W24: =IF(AND(V24=E24,F24=E24),"OK","DIFF")
A25: Ammunition bunker | B25: buildings | C25: 1 | D25: 36 | E25: 36 | F25: =IF(ISNUMBER(D25),C25*D25,E25) | H25: 12 | I25: 2 | L25: 10 | N25: 8 | O25: 4 | V25: =SUM(G25:U25) | W25: =IF(AND(V25=E25,F25=E25),"OK","DIFF")
A26: Guard tower | B26: buildings | C26: 4 | D26: 37 | E26: 148 | F26: =IF(ISNUMBER(D26),C26*D26,E26) | H26: 44 | L26: 8 | O26: 96 | V26: =SUM(G26:U26) | W26: =IF(AND(V26=E26,F26=E26),"OK","DIFF")
A27: Watchtower | B27: buildings | C27: 1 | D27: 26 | E27: 26 | F27: =IF(ISNUMBER(D27),C27*D27,E27) | H27: 5 | L27: 1 | O27: 19 | Q27: 1 | V27: =SUM(G27:U27) | W27: =IF(AND(V27=E27,F27=E27),"OK","DIFF")
A28: Fuel depot | B28: buildings | C28: 1 | D28: 20 | E28: 20 | F28: =IF(ISNUMBER(D28),C28*D28,E28) | H28: 8 | L28: 2 | O28: 10 | V28: =SUM(G28:U28) | W28: =IF(AND(V28=E28,F28=E28),"OK","DIFF")
A29: Quonset hut | B29: buildings | C29: 3 | D29: 19 | E29: 57 | F29: =IF(ISNUMBER(D29),C29*D29,E29) | H29: 42 | L29: 6 | O29: 9 | V29: =SUM(G29:U29) | W29: =IF(AND(V29=E29,F29=E29),"OK","DIFF")
A30: Radio mast | B30: buildings | C30: 1 | D30: 20 | E30: 20 | F30: =IF(ISNUMBER(D30),C30*D30,E30) | H30: 5 | L30: 2 | O30: 13 | V30: =SUM(G30:U30) | W30: =IF(AND(V30=E30,F30=E30),"OK","DIFF")
A31: Camouflaged tent | B31: buildings | C31: 1 | D31: 14 | E31: 14 | F31: =IF(ISNUMBER(D31),C31*D31,E31) | H31: 3 | L31: 4 | O31: 7 | V31: =SUM(G31:U31) | W31: =IF(AND(V31=E31,F31=E31),"OK","DIFF")
A32: Container | B32: buildings | C32: 2 | D32: 11 | E32: 22 | F32: =IF(ISNUMBER(D32),C32*D32,E32) | G32: 12 | H32: 6 | O32: 4 | V32: =SUM(G32:U32) | W32: =IF(AND(V32=E32,F32=E32),"OK","DIFF")
A33: Guard booth | B33: buildings | C33: 1 | D33: 11 | E33: 11 | F33: =IF(ISNUMBER(D33),C33*D33,E33) | H33: 8 | O33: 3 | V33: =SUM(G33:U33) | W33: =IF(AND(V33=E33,F33=E33),"OK","DIFF")
A34: UAV pad | B34: buildings | C34: 2 | D34: 9 | E34: 18 | F34: =IF(ISNUMBER(D34),C34*D34,E34) | H34: 4 | L34: 8 | O34: 4 | S34: 2 | V34: =SUM(G34:U34) | W34: =IF(AND(V34=E34,F34=E34),"OK","DIFF")
A35: HESCO perimeter | B35: fortifications | C35: 1 | D35: 244 | E35: 244 | F35: =IF(ISNUMBER(D35),C35*D35,E35) | H35: 244 | V35: =SUM(G35:U35) | W35: =IF(AND(V35=E35,F35=E35),"OK","DIFF")
A36: Concertina wire | B36: fortifications | C36: 1 | D36: 102 | E36: 102 | F36: =IF(ISNUMBER(D36),C36*D36,E36) | O36: 50 | T36: 52 | V36: =SUM(G36:U36) | W36: =IF(AND(V36=E36,F36=E36),"OK","DIFF")
A37: Perimeter fence | B37: fortifications | C37: 1 | D37: 86 | E37: 86 | F37: =IF(ISNUMBER(D37),C37*D37,E37) | H37: 1 | O37: 85 | V37: =SUM(G37:U37) | W37: =IF(AND(V37=E37,F37=E37),"OK","DIFF")
A38: Outer gate | B38: fortifications | C38: 1 | D38: 50 | E38: 50 | F38: =IF(ISNUMBER(D38),C38*D38,E38) | H38: 7 | K38: 2 | L38: 3 | N38: 34 | O38: 4 | V38: =SUM(G38:U38) | W38: =IF(AND(V38=E38,F38=E38),"OK","DIFF")
A39: Camouflage net | B39: fortifications | C39: 7 | D39: 37..84 | E39: 379 | F39: =IF(ISNUMBER(D39),C39*D39,E39) | H39: 297 | O39: 82 | V39: =SUM(G39:U39) | W39: =IF(AND(V39=E39,F39=E39),"OK","DIFF")
A40: Earth revetment | B40: fortifications | C40: 5 | D40: 48..60 | E40: 264 | F40: =IF(ISNUMBER(D40),C40*D40,E40) | H40: 45 | N40: 219 | V40: =SUM(G40:U40) | W40: =IF(AND(V40=E40,F40=E40),"OK","DIFF")
A41: Radar surround | B41: fortifications | C41: 1 | D41: 51 | E41: 51 | F41: =IF(ISNUMBER(D41),C41*D41,E41) | H41: 2 | O41: 49 | V41: =SUM(G41:U41) | W41: =IF(AND(V41=E41,F41=E41),"OK","DIFF")
...

Sheet Transform_Trace
A1: Transform_Trace: one real UAV vertex from local space to the window
A2: Legend: yellow = input from the code; white = formula.
A3: Source: ts --export-docs component UAV-14 'Arm Front-right' (S, R_deg, T, local_matrix, world_matrix, parent UAV-00 world_matrix); objects/Builder M = T Ry Rx Rz S; View_Projection sheet (V, P, viewport).
A5: Part | B5: UAV-14 Arm Front-right (Cube, createCube) | K5: Parent | M5: UAV-00 Autonomous UAV (root, R = (0, 180, 0), T = (0, 7.5, 12.5))
B6: x | C6: y | D6: z | E6: w
A7: S (scale) | B7: 0.025 | C7: 0.018 | D7: 0.22
A8: R_deg (pitch x, yaw y, roll z) | B8: 0 | C8: -45 | D8: 0
A9: T (m) | B9: -0.106066 | C9: 0 | D9: 0.106066
A10: local vertex p (cube corner) | B10: 0.5 | C10: 0.5 | D10: 0.5 | E10: 1 | F10: createCube() vertex 3 = (0.5, 0.5, 0.5), +X face (mesh_samples in the export)
B12: S = scale(Sx, Sy, Sz) | G12: Rx(pitch) | L12: Ry(yaw) | Q12: Rz(roll)
B13: =$B$7 | C13: 0 | D13: 0 | E13: 0 | G13: 1 | H13: 0 | I13: 0 | J13: 0 | L13: =COS(RADIANS($C$8)) | M13: 0 | N13: =SIN(RADIANS($C$8)) | O13: 0 | Q13: =COS(RADIANS($D$8)) | R13: =-SIN(RADIANS($D$8)) | S13: 0 | T13: 0
B14: 0 | C14: =$C$7 | D14: 0 | E14: 0 | G14: 0 | H14: =COS(RADIANS($B$8)) | I14: =-SIN(RADIANS($B$8)) | J14: 0 | L14: 0 | M14: 1 | N14: 0 | O14: 0 | Q14: =SIN(RADIANS($D$8)) | R14: =COS(RADIANS($D$8)) | S14: 0 | T14: 0
B15: 0 | C15: 0 | D15: =$D$7 | E15: 0 | G15: 0 | H15: =SIN(RADIANS($B$8)) | I15: =COS(RADIANS($B$8)) | J15: 0 | L15: =-SIN(RADIANS($C$8)) | M15: 0 | N15: =COS(RADIANS($C$8)) | O15: 0 | Q15: 0 | R15: 0 | S15: 1 | T15: 0
B16: 0 | C16: 0 | D16: 0 | E16: 1 | G16: 0 | H16: 0 | I16: 0 | J16: 1 | L16: 0 | M16: 0 | N16: 0 | O16: 1 | Q16: 0 | R16: 0 | S16: 0 | T16: 1
B18: T = translate(Tx, Ty, Tz) | G18: Ry Rx | L18: R = Ry Rx Rz | Q18: R S
B19: 1 | C19: 0 | D19: 0 | E19: =$B$9 | G19: =L13*G13+M13*G14+N13*G15+O13*G16 | H19: =L13*H13+M13*H14+N13*H15+O13*H16 | I19: =L13*I13+M13*I14+N13*I15+O13*I16 | J19: =L13*J13+M13*J14+N13*J15+O13*J16 | L19: =G19*Q13+H19*Q14+I19*Q15+J19*Q16 | M19: =G19*R13+H19*R14+I19*R15+J19*R16 | N19: =G19*S13+H19*S14+I19*S15+J19*S16 | O19: =G19*T13+H19*T14+I19*T15+J19*T16 | Q19: =L19*B13+M19*B14+N19*B15+O19*B16 | R19: =L19*C13+M19*C14+N19*C15+O19*C16 | S19: =L19*D13+M19*D14+N19*D15+O19*D16 | T19: =L19*E13+M19*E14+N19*E15+O19*E16
B20: 0 | C20: 1 | D20: 0 | E20: =$C$9 | G20: =L14*G13+M14*G14+N14*G15+O14*G16 | H20: =L14*H13+M14*H14+N14*H15+O14*H16 | I20: =L14*I13+M14*I14+N14*I15+O14*I16 | J20: =L14*J13+M14*J14+N14*J15+O14*J16 | L20: =G20*Q13+H20*Q14+I20*Q15+J20*Q16 | M20: =G20*R13+H20*R14+I20*R15+J20*R16 | N20: =G20*S13+H20*S14+I20*S15+J20*S16 | O20: =G20*T13+H20*T14+I20*T15+J20*T16 | Q20: =L20*B13+M20*B14+N20*B15+O20*B16 | R20: =L20*C13+M20*C14+N20*C15+O20*C16 | S20: =L20*D13+M20*D14+N20*D15+O20*D16 | T20: =L20*E13+M20*E14+N20*E15+O20*E16
B21: 0 | C21: 0 | D21: 1 | E21: =$D$9 | G21: =L15*G13+M15*G14+N15*G15+O15*G16 | H21: =L15*H13+M15*H14+N15*H15+O15*H16 | I21: =L15*I13+M15*I14+N15*I15+O15*I16 | J21: =L15*J13+M15*J14+N15*J15+O15*J16 | L21: =G21*Q13+H21*Q14+I21*Q15+J21*Q16 | M21: =G21*R13+H21*R14+I21*R15+J21*R16 | N21: =G21*S13+H21*S14+I21*S15+J21*S16 | O21: =G21*T13+H21*T14+I21*T15+J21*T16 | Q21: =L21*B13+M21*B14+N21*B15+O21*B16 | R21: =L21*C13+M21*C14+N21*C15+O21*C16 | S21: =L21*D13+M21*D14+N21*D15+O21*D16 | T21: =L21*E13+M21*E14+N21*E15+O21*E16
B22: 0 | C22: 0 | D22: 0 | E22: 1 | G22: =L16*G13+M16*G14+N16*G15+O16*G16 | H22: =L16*H13+M16*H14+N16*H15+O16*H16 | I22: =L16*I13+M16*I14+N16*I15+O16*I16 | J22: =L16*J13+M16*J14+N16*J15+O16*J16 | L22: =G22*Q13+H22*Q14+I22*Q15+J22*Q16 | M22: =G22*R13+H22*R14+I22*R15+J22*R16 | N22: =G22*S13+H22*S14+I22*S15+J22*S16 | O22: =G22*T13+H22*T14+I22*T15+J22*T16 | Q22: =L22*B13+M22*B14+N22*B15+O22*B16 | R22: =L22*C13+M22*C14+N22*C15+O22*C16 | S22: =L22*D13+M22*D14+N22*D15+O22*D16 | T22: =L22*E13+M22*E14+N22*E15+O22*E16
B24: M = T R S (local matrix) | G24: M exported (local_matrix) | L24: |M - M exported| | Q24: Parent world (UAV-00, exported)
B25: =B19*Q19+C19*Q20+D19*Q21+E19*Q22 | C25: =B19*R19+C19*R20+D19*R21+E19*R22 | D25: =B19*S19+C19*S20+D19*S21+E19*S22 | E25: =B19*T19+C19*T20+D19*T21+E19*T22 | G25: 0.01767767 | H25: 0 | I25: -0.15556349 | J25: -0.10606602 | L25: =ABS(B25-G25) | M25: =ABS(C25-H25) | N25: =ABS(D25-I25) | O25: =ABS(E25-J25) | Q25: -1 | R25: 0 | S25: -8.7e-08 | T25: 0
B26: =B20*Q19+C20*Q20+D20*Q21+E20*Q22 | C26: =B20*R19+C20*R20+D20*R21+E20*R22 | D26: =B20*S19+C20*S20+D20*S21+E20*S22 | E26: =B20*T19+C20*T20+D20*T21+E20*T22 | G26: 0 | H26: 0.017999999 | I26: 0 | J26: 0 | L26: =ABS(B26-G26) | M26: =ABS(C26-H26) | N26: =ABS(D26-I26) | O26: =ABS(E26-J26) | Q26: 0 | R26: 1 | S26: 0 | T26: 7.5
B27: =B21*Q19+C21*Q20+D21*Q21+E21*Q22 | C27: =B21*R19+C21*R20+D21*R21+E21*R22 | D27: =B21*S19+C21*S20+D21*S21+E21*S22 | E27: =B21*T19+C21*T20+D21*T21+E21*T22 | G27: 0.01767767 | H27: 0 | I27: 0.15556349 | J27: 0.10606602 | L27: =ABS(B27-G27) | M27: =ABS(C27-H27) | N27: =ABS(D27-I27) | O27: =ABS(E27-J27) | Q27: 8.7e-08 | R27: 0 | S27: -1 | T27: 12.5
B28: =B22*Q19+C22*Q20+D22*Q21+E22*Q22 | C28: =B22*R19+C22*R20+D22*R21+E22*R22 | D28: =B22*S19+C22*S20+D22*S21+E22*S22 | E28: =B22*T19+C22*T20+D22*T21+E22*T22 | G28: 0 | H28: 0 | I28: 0 | J28: 1 | L28: =ABS(B28-G28) | M28: =ABS(C28-H28) | N28: =ABS(D28-I28) | O28: =ABS(E28-J28) | Q28: 0 | R28: 0 | S28: 0 | T28: 1
B30: World = Parent M | G30: World exported (world_matrix) | L30: |World - World exported| | Q30: View V (View_Projection sheet)
B31: =Q25*B25+R25*B26+S25*B27+T25*B28 | C31: =Q25*C25+R25*C26+S25*C27+T25*C28 | D31: =Q25*D25+R25*D26+S25*D27+T25*D28 | E31: =Q25*E25+R25*E26+S25*E27+T25*E28 | G31: -0.017677672 | H31: 0 | I31: 0.15556347 | J31: 0.10606601 | L31: =ABS(B31-G31) | M31: =ABS(C31-H31) | N31: =ABS(D31-I31) | O31: =ABS(E31-J31) | Q31: ='View_Projection'!B28 | R31: ='View_Projection'!C28 | S31: ='View_Projection'!D28 | T31: ='View_Projection'!E28
B32: =Q26*B25+R26*B26+S26*B27+T26*B28 | C32: =Q26*C25+R26*C26+S26*C27+T26*C28 | D32: =Q26*D25+R26*D26+S26*D27+T26*D28 | E32: =Q26*E25+R26*E26+S26*E27+T26*E28 | G32: 0 | H32: 0.017999999 | I32: 0 | J32: 7.5 | L32: =ABS(B32-G32) | M32: =ABS(C32-H32) | N32: =ABS(D32-I32) | O32: =ABS(E32-J32) | Q32: ='View_Projection'!B29 | R32: ='View_Projection'!C29 | S32: ='View_Projection'!D29 | T32: ='View_Projection'!E29
B33: =Q27*B25+R27*B26+S27*B27+T27*B28 | C33: =Q27*C25+R27*C26+S27*C27+T27*C28 | D33: =Q27*D25+R27*D26+S27*D27+T27*D28 | E33: =Q27*E25+R27*E26+S27*E27+T27*E28 | G33: -0.017677669 | H33: 0 | I33: -0.1555635 | J33: 12.393934 | L33: =ABS(B33-G33) | M33: =ABS(C33-H33) | N33: =ABS(D33-I33) | O33: =ABS(E33-J33) | Q33: ='View_Projection'!B30 | R33: ='View_Projection'!C30 | S33: ='View_Projection'!D30 | T33: ='View_Projection'!E30
B34: =Q28*B25+R28*B26+S28*B27+T28*B28 | C34: =Q28*C25+R28*C26+S28*C27+T28*C28 | D34: =Q28*D25+R28*D26+S28*D27+T28*D28 | E34: =Q28*E25+R28*E26+S28*E27+T28*E28 | G34: 0 | H34: 0 | I34: 0 | J34: 1 | L34: =ABS(B34-G34) | M34: =ABS(C34-H34) | N34: =ABS(D34-I34) | O34: =ABS(E34-J34) | Q34: ='View_Projection'!B31 | R34: ='View_Projection'!C31 | S34: ='View_Projection'!D31 | T34: ='View_Projection'!E31
B36: Projection P (View_Projection sheet) | G36: Vertex pipeline (column vectors) | Q36: Checks
B37: ='View_Projection'!B35 | C37: ='View_Projection'!C35 | D37: ='View_Projection'!D35 | E37: ='View_Projection'!E35 | G37: stage | L37: x | M37: y | N37: z | O37: w | Q37: check | T37: value
B38: ='View_Projection'!B36 | C38: ='View_Projection'!C36 | D38: ='View_Projection'!D36 | E38: ='View_Projection'!E36 | G38: local p | L38: =B10 | M38: =C10 | N38: =D10 | O38: =E10 | Q38: max |M - export| | T38: =MAX(L25:O28)
B39: ='View_Projection'!B37 | C39: ='View_Projection'!C37 | D39: ='View_Projection'!D37 | E39: ='View_Projection'!E37 | G39: world = World p | L39: =B31*L38+C31*M38+D31*N38+E31*O38 | M39: =B32*L38+C32*M38+D32*N38+E32*O38 | N39: =B33*L38+C33*M38+D33*N38+E33*O38 | O39: =B34*L38+C34*M38+D34*N38+E34*O38 | Q39: max |World - export| | T39: =MAX(L31:O34)
B40: ='View_Projection'!B38 | C40: ='View_Projection'!C38 | D40: ='View_Projection'!D38 | E40: ='View_Projection'!E38 | G40: eye = V world | L40: =Q31*L39+R31*M39+S31*N39+T31*O39 | M40: =Q32*L39+R32*M39+S32*N39+T32*O39 | N40: =Q33*L39+R33*M39+S33*N39+T33*O39 | O40: =Q34*L39+R34*M39+S34*N39+T34*O39 | Q40: inside clip volume |x|,|y|,|z| <= w | T40: =IF(AND(ABS(L41)<=O41,ABS(M41)<=O41,ABS(N41)<=O41),"yes","no")
G41: clip = P eye | L41: =B37*L40+C37*M40+D37*N40+E37*O40 | M41: =B38*L40+C38*M40+D38*N40+E38*O40 | N41: =B39*L40+C39*M40+D39*N40+E39*O40 | O41: =B40*L40+C40*M40+D40*N40+E40*O40 | Q41: eye-space distance -z_eye (m) | T41: =-N40
G42: NDC = clip / w | L42: =L41/O41 | M42: =M41/O41 | N42: =N41/O41 | O42: =O41/O41
G43: window (x px, y px top-left, depth, -) | L43: =(L42*0.5+0.5)*'View_Projection'!$B$12 | M43: =(1-(M42*0.5+0.5))*'View_Projection'!$B$13 | N43: =N42*0.5+0.5 | O43: -
G44: Exported matrices are float32: differences of ~1e-7 are rounding. Window: x = (ndc.x/2+0.5) W, y = (1-(ndc.y/2+0.5)) H, d = ndc.z/2+0.5 (glDepthRange 0..1).

Sheet Vertex_Groups
A1: Vertex_Groups: parts built from unit primitives by matrices (report Section 7.1)
A2: Legend: yellow = input from the code; white = formula.
A3: Source: ts --export-docs: BNK-11 'Retaining wall W' (S, R_deg, T, parent world), cube corners (primitives P01), v6.garrison.gait (thigh, shin, cycle), UAV gimbal parts; objects/Builder M = T Ry Rx Rz S; scene/Gait legFK.
A5: A. Retaining wall W (BNK-11): unit cube -> world
B6: x | C6: y | D6: z
A7: S | B7: 0.35 | C7: 3.8571 | D7: 1.245
A8: R_deg | B8: 0 | C8: 0 | D8: 0
A9: T | B9: -1.675 | C9: -1.82145 | D9: 4.2625
B11: M = T Ry Rx Rz S | G11: W parent (export) | L11: W = W parent M | Q11: W exported
B12: =(COS(RADIANS($C$8))*COS(RADIANS($D$8))+SIN(RADIANS($C$8))*SIN(RADIANS($B$8))*SIN(RADIANS($D$8)))*$B$7 | C12: =(-COS(RADIANS($C$8))*SIN(RADIANS($D$8))+SIN(RADIANS($C$8))*SIN(RADIANS($B$8))*COS(RADIANS($D$8)))*$C$7 | D12: =(SIN(RADIANS($C$8))*COS(RADIANS($B$8)))*$D$7 | E12: =$B$9 | G12: 1 | H12: 0 | I12: 0 | J12: 0 | L12: =G12*B12+H12*B13+I12*B14+J12*B15 | M12: =G12*C12+H12*C13+I12*C14+J12*C15 | N12: =G12*D12+H12*D13+I12*D14+J12*D15 | O12: =G12*E12+H12*E13+I12*E14+J12*E15 | Q12: 0.35 | R12: 0 | S12: 0 | T12: -1.6749999
B13: =(COS(RADIANS($B$8))*SIN(RADIANS($D$8)))*$B$7 | C13: =(COS(RADIANS($B$8))*COS(RADIANS($D$8)))*$C$7 | D13: =(-SIN(RADIANS($B$8)))*$D$7 | E13: =$C$9 | G13: 0 | H13: 1 | I13: 0 | J13: 0 | L13: =G13*B12+H13*B13+I13*B14+J13*B15 | M13: =G13*C12+H13*C13+I13*C14+J13*C15 | N13: =G13*D12+H13*D13+I13*D14+J13*D15 | O13: =G13*E12+H13*E13+I13*E14+J13*E15 | Q13: 0 | R13: 3.8571 | S13: 0 | T13: -1.82145
B14: =(-SIN(RADIANS($C$8))*COS(RADIANS($D$8))+COS(RADIANS($C$8))*SIN(RADIANS($B$8))*SIN(RADIANS($D$8)))*$B$7 | C14: =(SIN(RADIANS($C$8))*SIN(RADIANS($D$8))+COS(RADIANS($C$8))*SIN(RADIANS($B$8))*COS(RADIANS($D$8)))*$C$7 | D14: =(COS(RADIANS($C$8))*COS(RADIANS($B$8)))*$D$7 | E14: =$D$9 | G14: 0 | H14: 0 | I14: 1 | J14: 0 | L14: =G14*B12+H14*B13+I14*B14+J14*B15 | M14: =G14*C12+H14*C13+I14*C14+J14*C15 | N14: =G14*D12+H14*D13+I14*D14+J14*D15 | O14: =G14*E12+H14*E13+I14*E14+J14*E15 | Q14: 0 | R14: 0 | S14: 1.2449999 | T14: 4.2624998
B15: 0 | C15: 0 | D15: 0 | E15: 1 | G15: 0 | H15: 0 | I15: 0 | J15: 1 | L15: =G15*B12+H15*B13+I15*B14+J15*B15 | M15: =G15*C12+H15*C13+I15*C14+J15*C15 | N15: =G15*D12+H15*D13+I15*D14+J15*D15 | O15: =G15*E12+H15*E13+I15*E14+J15*E15 | Q15: 0 | R15: 0 | S15: 0 | T15: 1
Q16: max |W - W exported| | T16: =MAX(ABS(L12-Q12),ABS(M12-R12),ABS(N12-S12),ABS(O12-T12),ABS(L13-Q13),ABS(M13-R13),ABS(N13-S13),ABS(O13-T13),ABS(L14-Q14),ABS(M14-R14),ABS(N14-S14),ABS(O14-T14),ABS(L15-Q15),ABS(M15-R15),ABS(N15-S15),ABS(O15-T15))
L17: C. Leg FK: x = L1 sin h + L2 sin(h - k), y = -L1 cos h - L2 cos(h - k)
A18: corner | B18: x | C18: y | D18: z | E18: w | G18: world x | H18: world y | I18: world z | L18: L1 thigh | M18: 0.46 | N18: L2 shin | O18: 0.44
A19: v0 | B19: 0.5 | C19: -0.5 | D19: 0.5 | E19: 1 | G19: =L12*B19+M12*C19+N12*D19+O12*E19 | H19: =L13*B19+M13*C19+N13*D19+O13*E19 | I19: =L14*B19+M14*C19+N14*D19+O14*E19 | L19: phase | M19: hip h | N19: knee k | O19: x FK | P19: y FK | Q19: x export | R19: y export | S19: |diff|
A20: v1 | B20: 0.5 | C20: -0.5 | D20: -0.5 | E20: 1 | G20: =L12*B20+M12*C20+N12*D20+O12*E20 | H20: =L13*B20+M13*C20+N13*D20+O13*E20 | I20: =L14*B20+M14*C20+N14*D20+O14*E20 | L20: 0 | M20: 32.771 | N20: 26.1137 | O20: =$M$18*SIN(RADIANS(M20))+$O$18*SIN(RADIANS(M20-N20)) | P20: =-$M$18*COS(RADIANS(M20))-$O$18*COS(RADIANS(M20-N20)) | Q20: 0.3 | R20: -0.82382 | S20: =SQRT((O20-Q20)^2+(P20-R20)^2)
A21: v2 | B21: 0.5 | C21: 0.5 | D21: -0.5 | E21: 1 | G21: =L12*B21+M12*C21+N12*D21+O12*E21 | H21: =L13*B21+M13*C21+N13*D21+O13*E21 | I21: =L14*B21+M14*C21+N14*D21+O14*E21 | L21: 0.125 | M21: 30.0534 | N21: 42.2385 | O21: =$M$18*SIN(RADIANS(M21))+$O$18*SIN(RADIANS(M21-N21)) | P21: =-$M$18*COS(RADIANS(M21))-$O$18*COS(RADIANS(M21-N21)) | Q21: 0.1375 | R21: -0.828244 | S21: =SQRT((O21-Q21)^2+(P21-R21)^2)
A22: v3 | B22: 0.5 | C22: 0.5 | D22: 0.5 | E22: 1 | G22: =L12*B22+M12*C22+N12*D22+O12*E22 | H22: =L13*B22+M13*C22+N13*D22+O13*E22 | I22: =L14*B22+M14*C22+N14*D22+O14*E22 | L22: 0.25 | M22: 15.7984 | N22: 35.7634 | O22: =$M$18*SIN(RADIANS(M22))+$O$18*SIN(RADIANS(M22-N22)) | P22: =-$M$18*COS(RADIANS(M22))-$O$18*COS(RADIANS(M22-N22)) | Q22: -0.025 | R22: -0.85618 | S22: =SQRT((O22-Q22)^2+(P22-R22)^2)
A23: v4 | B23: -0.5 | C23: -0.5 | D23: -0.5 | E23: 1 | G23: =L12*B23+M12*C23+N12*D23+O12*E23 | H23: =L13*B23+M13*C23+N13*D23+O13*E23 | I23: =L14*B23+M14*C23+N14*D23+O14*E23 | L23: 0.375 | M23: 1.5555 | N23: 28.5892 | O23: =$M$18*SIN(RADIANS(M23))+$O$18*SIN(RADIANS(M23-N23)) | P23: =-$M$18*COS(RADIANS(M23))-$O$18*COS(RADIANS(M23-N23)) | Q23: -0.1875 | R23: -0.851756 | S23: =SQRT((O23-Q23)^2+(P23-R23)^2)
A24: v5 | B24: -0.5 | C24: -0.5 | D24: 0.5 | E24: 1 | G24: =L12*B24+M12*C24+N12*D24+O12*E24 | H24: =L13*B24+M13*C24+N13*D24+O13*E24 | I24: =L14*B24+M14*C24+N14*D24+O14*E24 | L24: 0.5 | M24: -6.5205 | N24: 36.0684 | O24: =$M$18*SIN(RADIANS(M24))+$O$18*SIN(RADIANS(M24-N24)) | P24: =-$M$18*COS(RADIANS(M24))-$O$18*COS(RADIANS(M24-N24)) | Q24: -0.35 | R24: -0.780965 | S24: =SQRT((O24-Q24)^2+(P24-R24)^2)
A25: v6 | B25: -0.5 | C25: 0.5 | D25: 0.5 | E25: 1 | G25: =L12*B25+M12*C25+N12*D25+O12*E25 | H25: =L13*B25+M13*C25+N13*D25+O13*E25 | I25: =L14*B25+M14*C25+N14*D25+O14*E25 | L25: 0.625 | M25: -21.1388 | N25: 24.1828 | O25: =$M$18*SIN(RADIANS(M25))+$O$18*SIN(RADIANS(M25-N25)) | P25: =-$M$18*COS(RADIANS(M25))-$O$18*COS(RADIANS(M25-N25)) | Q25: -0.478757 | R25: -0.738423 | S25: =SQRT((O25-Q25)^2+(P25-R25)^2)
A26: v7 | B26: -0.5 | C26: 0.5 | D26: -0.5 | E26: 1 | G26: =L12*B26+M12*C26+N12*D26+O12*E26 | H26: =L13*B26+M13*C26+N13*D26+O13*E26 | I26: =L14*B26+M14*C26+N14*D26+O14*E26 | L26: 0.75 | M26: 8.2873 | N26: 59.2127 | O26: =$M$18*SIN(RADIANS(M26))+$O$18*SIN(RADIANS(M26-N26)) | P26: =-$M$18*COS(RADIANS(M26))-$O$18*COS(RADIANS(M26-N26)) | Q26: -0.275281 | R26: -0.732542 | S26: =SQRT((O26-Q26)^2+(P26-R26)^2)
L27: 0.875 | M27: 41.894 | N27: 59.9294 | O27: =$M$18*SIN(RADIANS(M27))+$O$18*SIN(RADIANS(M27-N27)) | P27: =-$M$18*COS(RADIANS(M27))-$O$18*COS(RADIANS(M27-N27)) | Q27: 0.170941 | R27: -0.760796 | S27: =SQRT((O27-Q27)^2+(P27-R27)^2)
L28: 1 | M28: 32.771 | N28: 26.1137 | O28: =$M$18*SIN(RADIANS(M28))+$O$18*SIN(RADIANS(M28-N28)) | P28: =-$M$18*COS(RADIANS(M28))-$O$18*COS(RADIANS(M28-N28)) | Q28: 0.3 | R28: -0.82382 | S28: =SQRT((O28-Q28)^2+(P28-R28)^2)
A29: D. UAV camera: view axis = R_UAV Ry(yaw) Rx(pitch) (0, 0, 1)
A30: yaw (deg) | B30: 0 | C30: pitch (deg) | D30: 50
B31: R_UAV (rotation of UAV-00 world, export) | G31: gimbal axis | I31: world view axis | K31: below horizon (deg)
B32: -1 | C32: 0 | D32: -1e-07 | G32: =SIN(RADIANS($B$30))*COS(RADIANS($D$30)) | I32: =B32*G32+C32*G33+D32*G34 | K32: =DEGREES(ASIN(-I33))
B33: 0 | C33: 1 | D33: 0 | G33: =-SIN(RADIANS($D$30)) | I33: =B33*G32+C33*G33+D33*G34
B34: 1e-07 | C34: 0 | D34: -1 | G34: =COS(RADIANS($B$30))*COS(RADIANS($D$30)) | I34: =B34*G32+C34*G33+D34*G34
A36: Change yaw / pitch (yellow): the axis turns; the pitch alone sets the angle below the horizon (the UAV flies level).

Sheet View_Projection
A1: View_Projection: default orbit camera, lookAt basis, perspective and depth
A2: Legend: yellow = input from the code; white = formula.
A3: Source: scene/Camera.h (target, yaw 32, pitch 27, distance 34, fov 50), Camera.cpp compute() (orbit eye), Math3D.cpp lookAt / perspective, near 0.05 far 600, 24-bit depth (FrameBuffers.cpp).
G4: Depth mapping (24-bit fixed point: step = 1 / (2^24 - 1))
A5: Input / derived | B5: x | C5: y | D5: z | G5: z_eye (m) | H5: z_ndc (near 0.05) | I5: depth d (near 0.05) | J5: metres per depth step (near 0.05) | K5: z_ndc (near 0.5) | L5: depth d (near 0.5) | M5: metres per depth step (near 0.5)
A6: target (m) | B6: 0 | C6: 0.8 | D6: 0 | G6: -0.05 | H6: =((-($B$15+$B$14)/($B$15-$B$14))*G6+(-2*$B$15*$B$14/($B$15-$B$14)))/(-G6) | I6: =0.5*H6+0.5 | J6: =(1/(2^24-1))*($B$15-$B$14)*G6^2/($B$15*$B$14) | K6: clipped | L6: clipped | M6: clipped
A7: up | B7: 0 | C7: 1 | D7: 0 | G7: -0.1 | H7: =((-($B$15+$B$14)/($B$15-$B$14))*G7+(-2*$B$15*$B$14/($B$15-$B$14)))/(-G7) | I7: =0.5*H7+0.5 | J7: =(1/(2^24-1))*($B$15-$B$14)*G7^2/($B$15*$B$14) | K7: clipped | L7: clipped | M7: clipped
A8: yaw (deg) | B8: 32 | G8: -0.5 | H8: =((-($B$15+$B$14)/($B$15-$B$14))*G8+(-2*$B$15*$B$14/($B$15-$B$14)))/(-G8) | I8: =0.5*H8+0.5 | J8: =(1/(2^24-1))*($B$15-$B$14)*G8^2/($B$15*$B$14) | K8: =((-($B$15+$B$16)/($B$15-$B$16))*G8+(-2*$B$15*$B$16/($B$15-$B$16)))/(-G8) | L8: =0.5*K8+0.5 | M8: =(1/(2^24-1))*($B$15-$B$16)*G8^2/($B$15*$B$16)
A9: pitch (deg) | B9: 27 | G9: -1 | H9: =((-($B$15+$B$14)/($B$15-$B$14))*G9+(-2*$B$15*$B$14/($B$15-$B$14)))/(-G9) | I9: =0.5*H9+0.5 | J9: =(1/(2^24-1))*($B$15-$B$14)*G9^2/($B$15*$B$14) | K9: =((-($B$15+$B$16)/($B$15-$B$16))*G9+(-2*$B$15*$B$16/($B$15-$B$16)))/(-G9) | L9: =0.5*K9+0.5 | M9: =(1/(2^24-1))*($B$15-$B$16)*G9^2/($B$15*$B$16)
A10: distance (m) | B10: 34 | G10: -2 | H10: =((-($B$15+$B$14)/($B$15-$B$14))*G10+(-2*$B$15*$B$14/($B$15-$B$14)))/(-G10) | I10: =0.5*H10+0.5 | J10: =(1/(2^24-1))*($B$15-$B$14)*G10^2/($B$15*$B$14) | K10: =((-($B$15+$B$16)/($B$15-$B$16))*G10+(-2*$B$15*$B$16/($B$15-$B$16)))/(-G10) | L10: =0.5*K10+0.5 | M10: =(1/(2^24-1))*($B$15-$B$16)*G10^2/($B$15*$B$16)
A11: fov y (deg) | B11: 50 | G11: -5 | H11: =((-($B$15+$B$14)/($B$15-$B$14))*G11+(-2*$B$15*$B$14/($B$15-$B$14)))/(-G11) | I11: =0.5*H11+0.5 | J11: =(1/(2^24-1))*($B$15-$B$14)*G11^2/($B$15*$B$14) | K11: =((-($B$15+$B$16)/($B$15-$B$16))*G11+(-2*$B$15*$B$16/($B$15-$B$16)))/(-G11) | L11: =0.5*K11+0.5 | M11: =(1/(2^24-1))*($B$15-$B$16)*G11^2/($B$15*$B$16)
A12: width (px) | B12: 1920 | G12: -10 | H12: =((-($B$15+$B$14)/($B$15-$B$14))*G12+(-2*$B$15*$B$14/($B$15-$B$14)))/(-G12) | I12: =0.5*H12+0.5 | J12: =(1/(2^24-1))*($B$15-$B$14)*G12^2/($B$15*$B$14) | K12: =((-($B$15+$B$16)/($B$15-$B$16))*G12+(-2*$B$15*$B$16/($B$15-$B$16)))/(-G12) | L12: =0.5*K12+0.5 | M12: =(1/(2^24-1))*($B$15-$B$16)*G12^2/($B$15*$B$16)
A13: height (px) | B13: 1080 | G13: -34 | H13: =((-($B$15+$B$14)/($B$15-$B$14))*G13+(-2*$B$15*$B$14/($B$15-$B$14)))/(-G13) | I13: =0.5*H13+0.5 | J13: =(1/(2^24-1))*($B$15-$B$14)*G13^2/($B$15*$B$14) | K13: =((-($B$15+$B$16)/($B$15-$B$16))*G13+(-2*$B$15*$B$16/($B$15-$B$16)))/(-G13) | L13: =0.5*K13+0.5 | M13: =(1/(2^24-1))*($B$15-$B$16)*G13^2/($B$15*$B$16)
A14: near (m) | B14: 0.05 | G14: -50 | H14: =((-($B$15+$B$14)/($B$15-$B$14))*G14+(-2*$B$15*$B$14/($B$15-$B$14)))/(-G14) | I14: =0.5*H14+0.5 | J14: =(1/(2^24-1))*($B$15-$B$14)*G14^2/($B$15*$B$14) | K14: =((-($B$15+$B$16)/($B$15-$B$16))*G14+(-2*$B$15*$B$16/($B$15-$B$16)))/(-G14) | L14: =0.5*K14+0.5 | M14: =(1/(2^24-1))*($B$15-$B$16)*G14^2/($B$15*$B$16)
A15: far (m) | B15: 600 | G15: -100 | H15: =((-($B$15+$B$14)/($B$15-$B$14))*G15+(-2*$B$15*$B$14/($B$15-$B$14)))/(-G15) | I15: =0.5*H15+0.5 | J15: =(1/(2^24-1))*($B$15-$B$14)*G15^2/($B$15*$B$14) | K15: =((-($B$15+$B$16)/($B$15-$B$16))*G15+(-2*$B$15*$B$16/($B$15-$B$16)))/(-G15) | L15: =0.5*K15+0.5 | M15: =(1/(2^24-1))*($B$15-$B$16)*G15^2/($B$15*$B$16)
A16: near, comparison (m) | B16: 0.5 | G16: -200 | H16: =((-($B$15+$B$14)/($B$15-$B$14))*G16+(-2*$B$15*$B$14/($B$15-$B$14)))/(-G16) | I16: =0.5*H16+0.5 | J16: =(1/(2^24-1))*($B$15-$B$14)*G16^2/($B$15*$B$14) | K16: =((-($B$15+$B$16)/($B$15-$B$16))*G16+(-2*$B$15*$B$16/($B$15-$B$16)))/(-G16) | L16: =0.5*K16+0.5 | M16: =(1/(2^24-1))*($B$15-$B$16)*G16^2/($B$15*$B$16)
A17: aspect = width / height | B17: =B12/B13 | G17: -400 | H17: =((-($B$15+$B$14)/($B$15-$B$14))*G17+(-2*$B$15*$B$14/($B$15-$B$14)))/(-G17) | I17: =0.5*H17+0.5 | J17: =(1/(2^24-1))*($B$15-$B$14)*G17^2/($B$15*$B$14) | K17: =((-($B$15+$B$16)/($B$15-$B$16))*G17+(-2*$B$15*$B$16/($B$15-$B$16)))/(-G17) | L17: =0.5*K17+0.5 | M17: =(1/(2^24-1))*($B$15-$B$16)*G17^2/($B$15*$B$16)
A18: eye = target + d (cos p sin y, sin p, cos p cos y) | B18: =B6+$B$10*COS(RADIANS($B$9))*SIN(RADIANS($B$8)) | C18: =C6+$B$10*SIN(RADIANS($B$9)) | D18: =D6+$B$10*COS(RADIANS($B$9))*COS(RADIANS($B$8)) | G18: -600 | H18: =((-($B$15+$B$14)/($B$15-$B$14))*G18+(-2*$B$15*$B$14/($B$15-$B$14)))/(-G18) | I18: =0.5*H18+0.5 | J18: =(1/(2^24-1))*($B$15-$B$14)*G18^2/($B$15*$B$14) | K18: =((-($B$15+$B$16)/($B$15-$B$16))*G18+(-2*$B$15*$B$16/($B$15-$B$16)))/(-G18) | L18: =0.5*K18+0.5 | M18: =(1/(2^24-1))*($B$15-$B$16)*G18^2/($B$15*$B$16)
A19: eye - target | B19: =B18-B6 | C19: =C18-C6 | D19: =D18-D6
A20: n = normalize(eye - target) | B20: =B19/SQRT(B19^2+C19^2+D19^2) | C20: =C19/SQRT(B19^2+C19^2+D19^2) | D20: =D19/SQRT(B19^2+C19^2+D19^2) | G20: Summary
A21: up x n | B21: =C7*D20-D7*C20 | C21: =D7*B20-B7*D20 | D21: =B7*C20-C7*B20 | G21: depth step at 100 m (m) | J21: =J15 | M21: =M15
A22: u = normalize(up x n) | B22: =B21/SQRT(B21^2+C21^2+D21^2) | C22: =C21/SQRT(B21^2+C21^2+D21^2) | D22: =D21/SQRT(B21^2+C21^2+D21^2) | G22: ratio near 0.05 / near 0.5 at 100 m | J22: =J15/M15
A23: v = n x u | B23: =C20*D22-D20*C22 | C23: =D20*B22-B20*D22 | D23: =B20*C22-C20*B22 | G23: share of [0, 1] depth used by the first 1 m | J23: =I9 | M23: =L9
A24: code: s = normalize(f x up), f = -n; |s - u| | B24: =ABS(-(C20*D7-D20*C7)-B22*SQRT(B21^2+C21^2+D21^2))+ABS(-(D20*B7-B20*D7)-C22*SQRT(B21^2+C21^2+D21^2))+ABS(-(B20*C7-C20*B7)-D22*SQRT(B21^2+C21^2+D21^2)) | G24: share of depth used beyond 10 m | J24: =1-I12 | M24: =1-L12
A25: u . v, u . n, v . n (orthogonal: 0) | B25: =B22*B23+C22*C23+D22*D23 | C25: =B22*B20+C22*C20+D22*D20 | D25: =B23*B20+C23*C20+D23*D20
G26: d = (F / (F - N)) (1 - N / |z|): precision falls with z^2.
B27: View V = lookAt(eye, target, up): rows u, v, n; last column -(axis . eye) | G27: Step size dz = step (F - N) z^2 / (F N): ten times the near plane = ten times finer steps.
A28: row 0 (u) | B28: =B22 | C28: =C22 | D28: =D22 | E28: =-(B22*B18+C22*C18+D22*D18) | G28: Two surfaces closer than one step at 100 m share a depth value: z-fighting.
A29: row 1 (v) | B29: =B23 | C29: =C23 | D29: =D23 | E29: =-(B23*B18+C23*C18+D23*D18) | G29: The code keeps near 0.05 m for the first-person views; 24-bit depth.
A30: row 2 (n) | B30: =B20 | C30: =C20 | D30: =D20 | E30: =-(B20*B18+C20*C18+D20*D18)
A31: row 3 | B31: 0 | C31: 0 | D31: 0 | E31: 1
A33: t = 1 / tan(fov / 2) | B33: =1/TAN(RADIANS($B$11)/2)
B34: Perspective P (Math3D perspective, OpenGL clip z in [-w, w])
A35: row 0 | B35: =$B$33/$B$17 | C35: 0 | D35: 0 | E35: 0
A36: row 1 | B36: 0 | C36: =$B$33 | D36: 0 | E36: 0
A37: row 2 | B37: 0 | C37: 0 | D37: =-($B$15+$B$14)/($B$15-$B$14) | E37: =-2*$B$15*$B$14/($B$15-$B$14)
A38: row 3 | B38: 0 | C38: 0 | D38: -1 | E38: 0
A40: Code (lookAt): f = normalize(target - eye), s = normalize(f x up), u' = s x f; rows s, u', -f. Since f = -n: s = u and u' = v, the same matrix.

Sheet Clipping
A1: Clipping: Cohen-Sutherland, Liang-Barsky, Sutherland-Hodgman (textbook worked example)
A2: Legend: yellow = input from the code; white = formula.
A3: Source: Worked textbook example (window and lines chosen for teaching). The code itself clips on the GPU (clip volume -w <= x, y, z <= w) and culls on the CPU with math/Frustum (6 planes, sphere test).
A5: Window | B5: xmin | C5: 0 | D5: xmax | E5: 10 | F5: ymin | G5: 0 | H5: ymax | I5: 8 | K5: Outcode bits T B R L = (y > ymax)(y < ymin)(x > xmax)(x < xmin); code = 8T + 4B + 2R + L
A7: 1. Cohen-Sutherland outcodes
A8: line | B8: x0 | C8: y0 | D8: x1 | E8: y1 | F8: T0 | G8: B0 | H8: R0 | I8: L0 | J8: code0 | K8: T1 | L8: B1 | M8: R1 | N8: L1 | O8: code1 | P8: bits 0 | Q8: bits 1 | R8: AND of codes | S8: decision
A9: L1 | B9: 2 | C9: 2 | D9: 8 | E9: 6 | F9: =IF(C9>$I$5,1,0) | G9: =IF(C9<$G$5,1,0) | H9: =IF(B9>$E$5,1,0) | I9: =IF(B9<$C$5,1,0) | J9: =8*F9+4*G9+2*H9+I9 | K9: =IF(E9>$I$5,1,0) | L9: =IF(E9<$G$5,1,0) | M9: =IF(D9>$E$5,1,0) | N9: =IF(D9<$C$5,1,0) | O9: =8*K9+4*L9+2*M9+N9 | P9: =F9&G9&H9&I9 | Q9: =K9&L9&M9&N9 | R9: =F9*K9+G9*L9+H9*M9+I9*N9 | S9: =IF(J9+O9=0,"accept (both inside)",IF(R9>0,"reject (same side)","clip (subdivide)"))
A10: L2 | B10: -2 | C10: -1 | D10: -1 | E10: 9 | F10: =IF(C10>$I$5,1,0) | G10: =IF(C10<$G$5,1,0) | H10: =IF(B10>$E$5,1,0) | I10: =IF(B10<$C$5,1,0) | J10: =8*F10+4*G10+2*H10+I10 | K10: =IF(E10>$I$5,1,0) | L10: =IF(E10<$G$5,1,0) | M10: =IF(D10>$E$5,1,0) | N10: =IF(D10<$C$5,1,0) | O10: =8*K10+4*L10+2*M10+N10 | P10: =F10&G10&H10&I10 | Q10: =K10&L10&M10&N10 | R10: =F10*K10+G10*L10+H10*M10+I10*N10 | S10: =IF(J10+O10=0,"accept (both inside)",IF(R10>0,"reject (same side)","clip (subdivide)"))
A11: L3 | B11: -3 | C11: 4 | D11: 6 | E11: 12 | F11: =IF(C11>$I$5,1,0) | G11: =IF(C11<$G$5,1,0) | H11: =IF(B11>$E$5,1,0) | I11: =IF(B11<$C$5,1,0) | J11: =8*F11+4*G11+2*H11+I11 | K11: =IF(E11>$I$5,1,0) | L11: =IF(E11<$G$5,1,0) | M11: =IF(D11>$E$5,1,0) | N11: =IF(D11<$C$5,1,0) | O11: =8*K11+4*L11+2*M11+N11 | P11: =F11&G11&H11&I11 | Q11: =K11&L11&M11&N11 | R11: =F11*K11+G11*L11+H11*M11+I11*N11 | S11: =IF(J11+O11=0,"accept (both inside)",IF(R11>0,"reject (same side)","clip (subdivide)"))
A12: L4 | B12: -2 | C12: 3 | D12: 12 | E12: 5 | F12: =IF(C12>$I$5,1,0) | G12: =IF(C12<$G$5,1,0) | H12: =IF(B12>$E$5,1,0) | I12: =IF(B12<$C$5,1,0) | J12: =8*F12+4*G12+2*H12+I12 | K12: =IF(E12>$I$5,1,0) | L12: =IF(E12<$G$5,1,0) | M12: =IF(D12>$E$5,1,0) | N12: =IF(D12<$C$5,1,0) | O12: =8*K12+4*L12+2*M12+N12 | P12: =F12&G12&H12&I12 | Q12: =K12&L12&M12&N12 | R12: =F12*K12+G12*L12+H12*M12+I12*N12 | S12: =IF(J12+O12=0,"accept (both inside)",IF(R12>0,"reject (same side)","clip (subdivide)"))
A14: 2. Liang-Barsky: x = x0 + t dx, y = y0 + t dy; p1 = -dx, q1 = x0 - xmin; p2 = dx, q2 = xmax - x0; p3 = -dy, q3 = y0 - ymin; p4 = dy, q4 = ymax - y0
A15: line | B15: dx | C15: dy | D15: p1 | E15: p2 | F15: p3 | G15: p4 | H15: q1 | I15: q2 | J15: q3 | K15: q4 | L15: t enter = max(0, q/p, p<0) | M15: t exit = min(1, q/p, p>0) | N15: parallel outside | O15: visible | P15: x0' | Q15: y0' | R15: x1' | S15: y1'
A16: =A9 | B16: =D9-B9 | C16: =E9-C9 | D16: =-B16 | E16: =B16 | F16: =-C16 | G16: =C16 | H16: =B9-$C$5 | I16: =$E$5-B9 | J16: =C9-$G$5 | K16: =$I$5-C9 | L16: =MAX(0,IF(D16<0,H16/D16,0),IF(E16<0,I16/E16,0),IF(F16<0,J16/F16,0),IF(G16<0,K16/G16,0)) | M16: =MIN(1,IF(D16>0,H16/D16,1),IF(E16>0,I16/E16,1),IF(F16>0,J16/F16,1),IF(G16>0,K16/G16,1)) | N16: =IF(OR(AND(D16=0,H16<0),AND(E16=0,I16<0),AND(F16=0,J16<0),AND(G16=0,K16<0)),"yes","no") | O16: =IF(AND(N16="no",L16<=M16),"yes","no") | P16: =IF(O16="yes",B9+L16*B16,"-") | Q16: =IF(O16="yes",C9+L16*C16,"-") | R16: =IF(O16="yes",B9+M16*B16,"-") | S16: =IF(O16="yes",C9+M16*C16,"-")
A17: =A10 | B17: =D10-B10 | C17: =E10-C10 | D17: =-B17 | E17: =B17 | F17: =-C17 | G17: =C17 | H17: =B10-$C$5 | I17: =$E$5-B10 | J17: =C10-$G$5 | K17: =$I$5-C10 | L17: =MAX(0,IF(D17<0,H17/D17,0),IF(E17<0,I17/E17,0),IF(F17<0,J17/F17,0),IF(G17<0,K17/G17,0)) | M17: =MIN(1,IF(D17>0,H17/D17,1),IF(E17>0,I17/E17,1),IF(F17>0,J17/F17,1),IF(G17>0,K17/G17,1)) | N17: =IF(OR(AND(D17=0,H17<0),AND(E17=0,I17<0),AND(F17=0,J17<0),AND(G17=0,K17<0)),"yes","no") | O17: =IF(AND(N17="no",L17<=M17),"yes","no") | P17: =IF(O17="yes",B10+L17*B17,"-") | Q17: =IF(O17="yes",C10+L17*C17,"-") | R17: =IF(O17="yes",B10+M17*B17,"-") | S17: =IF(O17="yes",C10+M17*C17,"-")
A18: =A11 | B18: =D11-B11 | C18: =E11-C11 | D18: =-B18 | E18: =B18 | F18: =-C18 | G18: =C18 | H18: =B11-$C$5 | I18: =$E$5-B11 | J18: =C11-$G$5 | K18: =$I$5-C11 | L18: =MAX(0,IF(D18<0,H18/D18,0),IF(E18<0,I18/E18,0),IF(F18<0,J18/F18,0),IF(G18<0,K18/G18,0)) | M18: =MIN(1,IF(D18>0,H18/D18,1),IF(E18>0,I18/E18,1),IF(F18>0,J18/F18,1),IF(G18>0,K18/G18,1)) | N18: =IF(OR(AND(D18=0,H18<0),AND(E18=0,I18<0),AND(F18=0,J18<0),AND(G18=0,K18<0)),"yes","no") | O18: =IF(AND(N18="no",L18<=M18),"yes","no") | P18: =IF(O18="yes",B11+L18*B18,"-") | Q18: =IF(O18="yes",C11+L18*C18,"-") | R18: =IF(O18="yes",B11+M18*B18,"-") | S18: =IF(O18="yes",C11+M18*C18,"-")
A19: =A12 | B19: =D12-B12 | C19: =E12-C12 | D19: =-B19 | E19: =B19 | F19: =-C19 | G19: =C19 | H19: =B12-$C$5 | I19: =$E$5-B12 | J19: =C12-$G$5 | K19: =$I$5-C12 | L19: =MAX(0,IF(D19<0,H19/D19,0),IF(E19<0,I19/E19,0),IF(F19<0,J19/F19,0),IF(G19<0,K19/G19,0)) | M19: =MIN(1,IF(D19>0,H19/D19,1),IF(E19>0,I19/E19,1),IF(F19>0,J19/F19,1),IF(G19>0,K19/G19,1)) | N19: =IF(OR(AND(D19=0,H19<0),AND(E19=0,I19<0),AND(F19=0,J19<0),AND(G19=0,K19<0)),"yes","no") | O19: =IF(AND(N19="no",L19<=M19),"yes","no") | P19: =IF(O19="yes",B12+L19*B19,"-") | Q19: =IF(O19="yes",C12+L19*C19,"-") | R19: =IF(O19="yes",B12+M19*B19,"-") | S19: =IF(O19="yes",C12+M19*C19,"-")
A21: 3. Sutherland-Hodgman: triangle clipped against the 4 window edges in turn (output list -> next stage input)
A22: Triangle | B22: A | C22: -2 | D22: 3 | E22: B | F22: 7 | G22: -2 | H22: C | I22: 12 | J22: 10
A23: Stage 1: left x >= xmin | L23: Stage 2: right x <= xmax
A24: edge | B24: Sx | C24: Sy | D24: Px | E24: Py | F24: S in | G24: P in | H24: Ix | I24: Iy | J24: output | L24: edge | M24: Sx | N24: Sy | O24: Px | P24: Py | Q24: S in | R24: P in | S24: Ix | T24: Iy | U24: output
A25: 1-2 | B25: =C22 | C25: =D22 | D25: =F22 | E25: =G22 | F25: =IF(B25>=$C$5,1,0) | G25: =IF(D25>=$C$5,1,0) | H25: =IF(F25<>G25,$C$5,"-") | I25: =IF(F25<>G25,C25+($C$5-B25)*(E25-C25)/(D25-B25),"-") | J25: =IF(F25+G25=2,"P",IF(G25=1,"I, P",IF(F25=1,"I","none"))) | L25: 1-2 | M25: =H25 | N25: =I25 | O25: =D25 | P25: =E25 | Q25: =IF(M25<=$E$5,1,0) | R25: =IF(O25<=$E$5,1,0) | S25: =IF(Q25<>R25,$E$5,"-") | T25: =IF(Q25<>R25,N25+($E$5-M25)*(P25-N25)/(O25-M25),"-") | U25: =IF(Q25+R25=2,"P",IF(R25=1,"I, P",IF(Q25=1,"I","none")))
A26: 2-3 | B26: =F22 | C26: =G22 | D26: =I22 | E26: =J22 | F26: =IF(B26>=$C$5,1,0) | G26: =IF(D26>=$C$5,1,0) | H26: =IF(F26<>G26,$C$5,"-") | I26: =IF(F26<>G26,C26+($C$5-B26)*(E26-C26)/(D26-B26),"-") | J26: =IF(F26+G26=2,"P",IF(G26=1,"I, P",IF(F26=1,"I","none"))) | L26: 2-3 | M26: =D25 | N26: =E25 | O26: =D26 | P26: =E26 | Q26: =IF(M26<=$E$5,1,0) | R26: =IF(O26<=$E$5,1,0) | S26: =IF(Q26<>R26,$E$5,"-") | T26: =IF(Q26<>R26,N26+($E$5-M26)*(P26-N26)/(O26-M26),"-") | U26: =IF(Q26+R26=2,"P",IF(R26=1,"I, P",IF(Q26=1,"I","none")))
A27: 3-1 | B27: =I22 | C27: =J22 | D27: =C22 | E27: =D22 | F27: =IF(B27>=$C$5,1,0) | G27: =IF(D27>=$C$5,1,0) | H27: =IF(F27<>G27,$C$5,"-") | I27: =IF(F27<>G27,C27+($C$5-B27)*(E27-C27)/(D27-B27),"-") | J27: =IF(F27+G27=2,"P",IF(G27=1,"I, P",IF(F27=1,"I","none"))) | L27: 3-4 | M27: =D26 | N27: =E26 | O27: =H27 | P27: =I27 | Q27: =IF(M27<=$E$5,1,0) | R27: =IF(O27<=$E$5,1,0) | S27: =IF(Q27<>R27,$E$5,"-") | T27: =IF(Q27<>R27,N27+($E$5-M27)*(P27-N27)/(O27-M27),"-") | U27: =IF(Q27+R27=2,"P",IF(R27=1,"I, P",IF(Q27=1,"I","none")))
A28: out | B28: ="("&ROUND(H25,2)&", "&ROUND(I25,2)&")"&" "&"("&ROUND(D25,2)&", "&ROUND(E25,2)&")"&" "&"("&ROUND(D26,2)&", "&ROUND(E26,2)&")"&" "&"("&ROUND(H27,2)&", "&ROUND(I27,2)&")" | L28: 4-1 | M28: =H27 | N28: =I27 | O28: =H25 | P28: =I25 | Q28: =IF(M28<=$E$5,1,0) | R28: =IF(O28<=$E$5,1,0) | S28: =IF(Q28<>R28,$E$5,"-") | T28: =IF(Q28<>R28,N28+($E$5-M28)*(P28-N28)/(O28-M28),"-") | U28: =IF(Q28+R28=2,"P",IF(R28=1,"I, P",IF(Q28=1,"I","none")))
A29: 4 vertices | L29: out | M29: ="("&ROUND(O25,2)&", "&ROUND(P25,2)&")"&" "&"("&ROUND(S26,2)&", "&ROUND(T26,2)&")"&" "&"("&ROUND(S27,2)&", "&ROUND(T27,2)&")"&" "&"("&ROUND(O27,2)&", "&ROUND(P27,2)&")"&" "&"("&ROUND(O28,2)&", "&ROUND(P28,2)&")"
L30: 5 vertices
A32: Stage 3: bottom y >= ymin | L32: Stage 4: top y <= ymax
A33: edge | B33: Sx | C33: Sy | D33: Px | E33: Py | F33: S in | G33: P in | H33: Ix | I33: Iy | J33: output | L33: edge | M33: Sx | N33: Sy | O33: Px | P33: Py | Q33: S in | R33: P in | S33: Ix | T33: Iy | U33: output
A34: 1-2 | B34: =O25 | C34: =P25 | D34: =S26 | E34: =T26 | F34: =IF(C34>=$G$5,1,0) | G34: =IF(E34>=$G$5,1,0) | H34: =IF(F34<>G34,B34+($G$5-C34)*(D34-B34)/(E34-C34),"-") | I34: =IF(F34<>G34,$G$5,"-") | J34: =IF(F34+G34=2,"P",IF(G34=1,"I, P",IF(F34=1,"I","none"))) | L34: 1-2 | M34: =H34 | N34: =I34 | O34: =D34 | P34: =E34 | Q34: =IF(N34<=$I$5,1,0) | R34: =IF(P34<=$I$5,1,0) | S34: =IF(Q34<>R34,M34+($I$5-N34)*(O34-M34)/(P34-N34),"-") | T34: =IF(Q34<>R34,$I$5,"-") | U34: =IF(Q34+R34=2,"P",IF(R34=1,"I, P",IF(Q34=1,"I","none")))
A35: 2-3 | B35: =S26 | C35: =T26 | D35: =S27 | E35: =T27 | F35: =IF(C35>=$G$5,1,0) | G35: =IF(E35>=$G$5,1,0) | H35: =IF(F35<>G35,B35+($G$5-C35)*(D35-B35)/(E35-C35),"-") | I35: =IF(F35<>G35,$G$5,"-") | J35: =IF(F35+G35=2,"P",IF(G35=1,"I, P",IF(F35=1,"I","none"))) | L35: 2-3 | M35: =D34 | N35: =E34 | O35: =D35 | P35: =E35 | Q35: =IF(N35<=$I$5,1,0) | R35: =IF(P35<=$I$5,1,0) | S35: =IF(Q35<>R35,M35+($I$5-N35)*(O35-M35)/(P35-N35),"-") | T35: =IF(Q35<>R35,$I$5,"-") | U35: =IF(Q35+R35=2,"P",IF(R35=1,"I, P",IF(Q35=1,"I","none")))
A36: 3-4 | B36: =S27 | C36: =T27 | D36: =O27 | E36: =P27 | F36: =IF(C36>=$G$5,1,0) | G36: =IF(E36>=$G$5,1,0) | H36: =IF(F36<>G36,B36+($G$5-C36)*(D36-B36)/(E36-C36),"-") | I36: =IF(F36<>G36,$G$5,"-") | J36: =IF(F36+G36=2,"P",IF(G36=1,"I, P",IF(F36=1,"I","none"))) | L36: 3-4 | M36: =D35 | N36: =E35 | O36: =D36 | P36: =E36 | Q36: =IF(N36<=$I$5,1,0) | R36: =IF(P36<=$I$5,1,0) | S36: =IF(Q36<>R36,M36+($I$5-N36)*(O36-M36)/(P36-N36),"-") | T36: =IF(Q36<>R36,$I$5,"-") | U36: =IF(Q36+R36=2,"P",IF(R36=1,"I, P",IF(Q36=1,"I","none")))
A37: 4-5 | B37: =O27 | C37: =P27 | D37: =O28 | E37: =P28 | F37: =IF(C37>=$G$5,1,0) | G37: =IF(E37>=$G$5,1,0) | H37: =IF(F37<>G37,B37+($G$5-C37)*(D37-B37)/(E37-C37),"-") | I37: =IF(F37<>G37,$G$5,"-") | J37: =IF(F37+G37=2,"P",IF(G37=1,"I, P",IF(F37=1,"I","none"))) | L37: 4-5 | M37: =D36 | N37: =E36 | O37: =D37 | P37: =E37 | Q37: =IF(N37<=$I$5,1,0) | R37: =IF(P37<=$I$5,1,0) | S37: =IF(Q37<>R37,M37+($I$5-N37)*(O37-M37)/(P37-N37),"-") | T37: =IF(Q37<>R37,$I$5,"-") | U37: =IF(Q37+R37=2,"P",IF(R37=1,"I, P",IF(Q37=1,"I","none")))
A38: 5-1 | B38: =O28 | C38: =P28 | D38: =O25 | E38: =P25 | F38: =IF(C38>=$G$5,1,0) | G38: =IF(E38>=$G$5,1,0) | H38: =IF(F38<>G38,B38+($G$5-C38)*(D38-B38)/(E38-C38),"-") | I38: =IF(F38<>G38,$G$5,"-") | J38: =IF(F38+G38=2,"P",IF(G38=1,"I, P",IF(F38=1,"I","none"))) | L38: 5-6 | M38: =D37 | N38: =E37 | O38: =H38 | P38: =I38 | Q38: =IF(N38<=$I$5,1,0) | R38: =IF(P38<=$I$5,1,0) | S38: =IF(Q38<>R38,M38+($I$5-N38)*(O38-M38)/(P38-N38),"-") | T38: =IF(Q38<>R38,$I$5,"-") | U38: =IF(Q38+R38=2,"P",IF(R38=1,"I, P",IF(Q38=1,"I","none")))
A39: out | B39: ="("&ROUND(H34,2)&", "&ROUND(I34,2)&")"&" "&"("&ROUND(D34,2)&", "&ROUND(E34,2)&")"&" "&"("&ROUND(D35,2)&", "&ROUND(E35,2)&")"&" "&"("&ROUND(D36,2)&", "&ROUND(E36,2)&")"&" "&"("&ROUND(D37,2)&", "&ROUND(E37,2)&")"&" "&"("&ROUND(H38,2)&", "&ROUND(I38,2)&")" | L39: 6-1 | M39: =H38 | N39: =I38 | O39: =H34 | P39: =I34 | Q39: =IF(N39<=$I$5,1,0) | R39: =IF(P39<=$I$5,1,0) | S39: =IF(Q39<>R39,M39+($I$5-N39)*(O39-M39)/(P39-N39),"-") | T39: =IF(Q39<>R39,$I$5,"-") | U39: =IF(Q39+R39=2,"P",IF(R39=1,"I, P",IF(Q39=1,"I","none")))
A40: 6 vertices | L40: out | M40: ="("&ROUND(O34,2)&", "&ROUND(P34,2)&")"&" "&"("&ROUND(S35,2)&", "&ROUND(T35,2)&")"&" "&"("&ROUND(S36,2)&", "&ROUND(T36,2)&")"&" "&"("&ROUND(O36,2)&", "&ROUND(P36,2)&")"&" "&"("&ROUND(O37,2)&", "&ROUND(P37,2)&")"&" "&"("&ROUND(O38,2)&", "&ROUND(P38,2)&")"&" "&"("&ROUND(O39,2)&", "&ROUND(P39,2)&")"
L41: 7 vertices
